2021-07-17 19:20:25.670 | INFO     | __main__:serve:56 - 启动服务：127.0.0.1:8091
2021-07-17 19:20:41.660 | ERROR    | grpc._server:_call_behavior:444 - An error has been caught in function '_call_behavior', process 'MainProcess' (38358), thread 'ThreadPoolExecutor-0_0' (123145415467008):
Traceback (most recent call last):

  File "/Users/jianxiyan/anaconda3/envs/mxshop_srvs/lib/python3.8/threading.py", line 890, in _bootstrap
    self._bootstrap_inner()
    │    └ <function Thread._bootstrap_inner at 0x1057980d0>
    └ <Thread(ThreadPoolExecutor-0_0, started daemon 123145415467008)>
  File "/Users/jianxiyan/anaconda3/envs/mxshop_srvs/lib/python3.8/threading.py", line 932, in _bootstrap_inner
    self.run()
    │    └ <function Thread.run at 0x105795dc0>
    └ <Thread(ThreadPoolExecutor-0_0, started daemon 123145415467008)>
  File "/Users/jianxiyan/anaconda3/envs/mxshop_srvs/lib/python3.8/threading.py", line 870, in run
    self._target(*self._args, **self._kwargs)
    │    │        │    │        │    └ {}
    │    │        │    │        └ <Thread(ThreadPoolExecutor-0_0, started daemon 123145415467008)>
    │    │        │    └ (<weakref at 0x107510950; to 'ThreadPoolExecutor' at 0x1074c9310>, <_queue.SimpleQueue object at 0x1074c74a0>, None, ())
    │    │        └ <Thread(ThreadPoolExecutor-0_0, started daemon 123145415467008)>
    │    └ <function _worker at 0x1074dcaf0>
    └ <Thread(ThreadPoolExecutor-0_0, started daemon 123145415467008)>
  File "/Users/jianxiyan/anaconda3/envs/mxshop_srvs/lib/python3.8/concurrent/futures/thread.py", line 80, in _worker
    work_item.run()
    │         └ <function _WorkItem.run at 0x1074dcc10>
    └ <concurrent.futures.thread._WorkItem object at 0x1075190d0>
  File "/Users/jianxiyan/anaconda3/envs/mxshop_srvs/lib/python3.8/concurrent/futures/thread.py", line 57, in run
    result = self.fn(*self.args, **self.kwargs)
             │    │   │    │       │    └ {}
             │    │   │    │       └ <concurrent.futures.thread._WorkItem object at 0x1075190d0>
             │    │   │    └ [<grpc._cython.cygrpc.RequestCallEvent object at 0x1075104f0>, <grpc._server._RPCState object at 0x107509eb0>, <bound method ...
             │    │   └ <concurrent.futures.thread._WorkItem object at 0x1075190d0>
             │    └ <function _unary_response_in_pool at 0x107507280>
             └ <concurrent.futures.thread._WorkItem object at 0x1075190d0>
  File "/Users/jianxiyan/anaconda3/envs/mxshop_srvs/lib/python3.8/site-packages/grpc/_server.py", line 561, in _unary_response_in_pool
    response, proceed = _call_behavior(rpc_event, state, behavior,
                        │              │          │      └ <bound method UserServicer.GetUserList of <user_srv.handler.user.UserServicer object at 0x1074e4100>>
                        │              │          └ <grpc._server._RPCState object at 0x107509eb0>
                        │              └ <grpc._cython.cygrpc.RequestCallEvent object at 0x1075104f0>
                        └ <function _call_behavior at 0x1074dde50>
> File "/Users/jianxiyan/anaconda3/envs/mxshop_srvs/lib/python3.8/site-packages/grpc/_server.py", line 444, in _call_behavior
    response_or_iterator = behavior(argument, context)
                           │        │         └ <grpc._server._Context object at 0x107519550>
                           │        └ pn: 2
                           │          pSize: 2
                           │          
                           └ <bound method UserServicer.GetUserList of <user_srv.handler.user.UserServicer object at 0x1074e4100>>

  File "/Users/jianxiyan/home/练习/go_python/mxshop/mxshop_srvs/user_srv/handler/user.py", line 39, in GetUserList
    if request.pSzie:
       └ pn: 2
         pSize: 2

AttributeError: pSzie
