2021-07-17 19:10:23.325 | INFO     | __main__:serve:56 - 启动服务：127.0.0.1:8091
2021-07-17 19:10:32.571 | ERROR    | grpc._server:_call_behavior:444 - An error has been caught in function '_call_behavior', process 'MainProcess' (37725), thread 'ThreadPoolExecutor-0_0' (123145507811328):
Traceback (most recent call last):

  File "/Users/jianxiyan/anaconda3/envs/mxshop_srvs/lib/python3.8/threading.py", line 890, in _bootstrap
    self._bootstrap_inner()
    │    └ <function Thread._bootstrap_inner at 0x10e77a0d0>
    └ <Thread(ThreadPoolExecutor-0_0, started daemon 123145507811328)>
  File "/Users/jianxiyan/anaconda3/envs/mxshop_srvs/lib/python3.8/threading.py", line 932, in _bootstrap_inner
    self.run()
    │    └ <function Thread.run at 0x10e777dc0>
    └ <Thread(ThreadPoolExecutor-0_0, started daemon 123145507811328)>
  File "/Users/jianxiyan/anaconda3/envs/mxshop_srvs/lib/python3.8/threading.py", line 870, in run
    self._target(*self._args, **self._kwargs)
    │    │        │    │        │    └ {}
    │    │        │    │        └ <Thread(ThreadPoolExecutor-0_0, started daemon 123145507811328)>
    │    │        │    └ (<weakref at 0x1104b59f0; to 'ThreadPoolExecutor' at 0x11046d310>, <_queue.SimpleQueue object at 0x11046c4a0>, None, ())
    │    │        └ <Thread(ThreadPoolExecutor-0_0, started daemon 123145507811328)>
    │    └ <function _worker at 0x110481a60>
    └ <Thread(ThreadPoolExecutor-0_0, started daemon 123145507811328)>
  File "/Users/jianxiyan/anaconda3/envs/mxshop_srvs/lib/python3.8/concurrent/futures/thread.py", line 80, in _worker
    work_item.run()
    │         └ <function _WorkItem.run at 0x110481b80>
    └ <concurrent.futures.thread._WorkItem object at 0x1104bd0d0>
  File "/Users/jianxiyan/anaconda3/envs/mxshop_srvs/lib/python3.8/concurrent/futures/thread.py", line 57, in run
    result = self.fn(*self.args, **self.kwargs)
             │    │   │    │       │    └ {}
             │    │   │    │       └ <concurrent.futures.thread._WorkItem object at 0x1104bd0d0>
             │    │   │    └ [<grpc._cython.cygrpc.RequestCallEvent object at 0x1104b54f0>, <grpc._server._RPCState object at 0x1104aeeb0>, <bound method ...
             │    │   └ <concurrent.futures.thread._WorkItem object at 0x1104bd0d0>
             │    └ <function _unary_response_in_pool at 0x1104ac1f0>
             └ <concurrent.futures.thread._WorkItem object at 0x1104bd0d0>
  File "/Users/jianxiyan/anaconda3/envs/mxshop_srvs/lib/python3.8/site-packages/grpc/_server.py", line 561, in _unary_response_in_pool
    response, proceed = _call_behavior(rpc_event, state, behavior,
                        │              │          │      └ <bound method UserServicer.GetUserList of <user_srv.handler.user.UserServicer object at 0x11048a100>>
                        │              │          └ <grpc._server._RPCState object at 0x1104aeeb0>
                        │              └ <grpc._cython.cygrpc.RequestCallEvent object at 0x1104b54f0>
                        └ <function _call_behavior at 0x1104aadc0>
> File "/Users/jianxiyan/anaconda3/envs/mxshop_srvs/lib/python3.8/site-packages/grpc/_server.py", line 444, in _call_behavior
    response_or_iterator = behavior(argument, context)
                           │        │         └ <grpc._server._Context object at 0x1104bd550>
                           │        └ pn: 2
                           │          pSize: 2
                           │          
                           └ <bound method UserServicer.GetUserList of <user_srv.handler.user.UserServicer object at 0x11048a100>>

  File "/Users/jianxiyan/home/练习/go_python/mxshop/mxshop_srvs/user_srv/handler/user.py", line 32, in GetUserList
    rsp = user_pb2.UserListResonse()
          └ <module 'user_srv.proto.user_pb2' from '/Users/jianxiyan/home/练习/go_python/mxshop/mxshop_srvs/user_srv/proto/user_pb2.py'>

AttributeError: module 'user_srv.proto.user_pb2' has no attribute 'UserListResonse'
2021-07-17 19:18:40.140 | ERROR    | grpc._server:_call_behavior:444 - An error has been caught in function '_call_behavior', process 'MainProcess' (37725), thread 'ThreadPoolExecutor-0_0' (123145507811328):
Traceback (most recent call last):

  File "/Users/jianxiyan/anaconda3/envs/mxshop_srvs/lib/python3.8/threading.py", line 890, in _bootstrap
    self._bootstrap_inner()
    │    └ <function Thread._bootstrap_inner at 0x10e77a0d0>
    └ <Thread(ThreadPoolExecutor-0_0, started daemon 123145507811328)>
  File "/Users/jianxiyan/anaconda3/envs/mxshop_srvs/lib/python3.8/threading.py", line 932, in _bootstrap_inner
    self.run()
    │    └ <function Thread.run at 0x10e777dc0>
    └ <Thread(ThreadPoolExecutor-0_0, started daemon 123145507811328)>
  File "/Users/jianxiyan/anaconda3/envs/mxshop_srvs/lib/python3.8/threading.py", line 870, in run
    self._target(*self._args, **self._kwargs)
    │    │        │    │        │    └ {}
    │    │        │    │        └ <Thread(ThreadPoolExecutor-0_0, started daemon 123145507811328)>
    │    │        │    └ (<weakref at 0x1104b59f0; to 'ThreadPoolExecutor' at 0x11046d310>, <_queue.SimpleQueue object at 0x11046c4a0>, None, ())
    │    │        └ <Thread(ThreadPoolExecutor-0_0, started daemon 123145507811328)>
    │    └ <function _worker at 0x110481a60>
    └ <Thread(ThreadPoolExecutor-0_0, started daemon 123145507811328)>
  File "/Users/jianxiyan/anaconda3/envs/mxshop_srvs/lib/python3.8/concurrent/futures/thread.py", line 80, in _worker
    work_item.run()
    │         └ <function _WorkItem.run at 0x110481b80>
    └ <concurrent.futures.thread._WorkItem object at 0x1104bd7c0>
  File "/Users/jianxiyan/anaconda3/envs/mxshop_srvs/lib/python3.8/concurrent/futures/thread.py", line 57, in run
    result = self.fn(*self.args, **self.kwargs)
             │    │   │    │       │    └ {}
             │    │   │    │       └ <concurrent.futures.thread._WorkItem object at 0x1104bd7c0>
             │    │   │    └ [<grpc._cython.cygrpc.RequestCallEvent object at 0x1104b5d60>, <grpc._server._RPCState object at 0x1104bd550>, <bound method ...
             │    │   └ <concurrent.futures.thread._WorkItem object at 0x1104bd7c0>
             │    └ <function _unary_response_in_pool at 0x1104ac1f0>
             └ <concurrent.futures.thread._WorkItem object at 0x1104bd7c0>
  File "/Users/jianxiyan/anaconda3/envs/mxshop_srvs/lib/python3.8/site-packages/grpc/_server.py", line 561, in _unary_response_in_pool
    response, proceed = _call_behavior(rpc_event, state, behavior,
                        │              │          │      └ <bound method UserServicer.GetUserList of <user_srv.handler.user.UserServicer object at 0x11048a100>>
                        │              │          └ <grpc._server._RPCState object at 0x1104bd550>
                        │              └ <grpc._cython.cygrpc.RequestCallEvent object at 0x1104b5d60>
                        └ <function _call_behavior at 0x1104aadc0>
> File "/Users/jianxiyan/anaconda3/envs/mxshop_srvs/lib/python3.8/site-packages/grpc/_server.py", line 444, in _call_behavior
    response_or_iterator = behavior(argument, context)
                           │        │         └ <grpc._server._Context object at 0x1104bd8b0>
                           │        └ pn: 2
                           │          pSize: 2
                           │          
                           └ <bound method UserServicer.GetUserList of <user_srv.handler.user.UserServicer object at 0x11048a100>>

  File "/Users/jianxiyan/home/练习/go_python/mxshop/mxshop_srvs/user_srv/handler/user.py", line 32, in GetUserList
    rsp = user_pb2.UserListResonse()
          └ <module 'user_srv.proto.user_pb2' from '/Users/jianxiyan/home/练习/go_python/mxshop/mxshop_srvs/user_srv/proto/user_pb2.py'>

AttributeError: module 'user_srv.proto.user_pb2' has no attribute 'UserListResonse'
2021-07-17 19:19:00.739 | ERROR    | grpc._server:_call_behavior:444 - An error has been caught in function '_call_behavior', process 'MainProcess' (37725), thread 'ThreadPoolExecutor-0_0' (123145507811328):
Traceback (most recent call last):

  File "/Users/jianxiyan/anaconda3/envs/mxshop_srvs/lib/python3.8/threading.py", line 890, in _bootstrap
    self._bootstrap_inner()
    │    └ <function Thread._bootstrap_inner at 0x10e77a0d0>
    └ <Thread(ThreadPoolExecutor-0_0, started daemon 123145507811328)>
  File "/Users/jianxiyan/anaconda3/envs/mxshop_srvs/lib/python3.8/threading.py", line 932, in _bootstrap_inner
    self.run()
    │    └ <function Thread.run at 0x10e777dc0>
    └ <Thread(ThreadPoolExecutor-0_0, started daemon 123145507811328)>
  File "/Users/jianxiyan/anaconda3/envs/mxshop_srvs/lib/python3.8/threading.py", line 870, in run
    self._target(*self._args, **self._kwargs)
    │    │        │    │        │    └ {}
    │    │        │    │        └ <Thread(ThreadPoolExecutor-0_0, started daemon 123145507811328)>
    │    │        │    └ (<weakref at 0x1104b59f0; to 'ThreadPoolExecutor' at 0x11046d310>, <_queue.SimpleQueue object at 0x11046c4a0>, None, ())
    │    │        └ <Thread(ThreadPoolExecutor-0_0, started daemon 123145507811328)>
    │    └ <function _worker at 0x110481a60>
    └ <Thread(ThreadPoolExecutor-0_0, started daemon 123145507811328)>
  File "/Users/jianxiyan/anaconda3/envs/mxshop_srvs/lib/python3.8/concurrent/futures/thread.py", line 80, in _worker
    work_item.run()
    │         └ <function _WorkItem.run at 0x110481b80>
    └ <concurrent.futures.thread._WorkItem object at 0x1104bd6d0>
  File "/Users/jianxiyan/anaconda3/envs/mxshop_srvs/lib/python3.8/concurrent/futures/thread.py", line 57, in run
    result = self.fn(*self.args, **self.kwargs)
             │    │   │    │       │    └ {}
             │    │   │    │       └ <concurrent.futures.thread._WorkItem object at 0x1104bd6d0>
             │    │   │    └ [<grpc._cython.cygrpc.RequestCallEvent object at 0x1104fb590>, <grpc._server._RPCState object at 0x1104aebb0>, <bound method ...
             │    │   └ <concurrent.futures.thread._WorkItem object at 0x1104bd6d0>
             │    └ <function _unary_response_in_pool at 0x1104ac1f0>
             └ <concurrent.futures.thread._WorkItem object at 0x1104bd6d0>
  File "/Users/jianxiyan/anaconda3/envs/mxshop_srvs/lib/python3.8/site-packages/grpc/_server.py", line 561, in _unary_response_in_pool
    response, proceed = _call_behavior(rpc_event, state, behavior,
                        │              │          │      └ <bound method UserServicer.GetUserList of <user_srv.handler.user.UserServicer object at 0x11048a100>>
                        │              │          └ <grpc._server._RPCState object at 0x1104aebb0>
                        │              └ <grpc._cython.cygrpc.RequestCallEvent object at 0x1104fb590>
                        └ <function _call_behavior at 0x1104aadc0>
> File "/Users/jianxiyan/anaconda3/envs/mxshop_srvs/lib/python3.8/site-packages/grpc/_server.py", line 444, in _call_behavior
    response_or_iterator = behavior(argument, context)
                           │        │         └ <grpc._server._Context object at 0x1104bdaf0>
                           │        └ pn: 2
                           │          pSize: 2
                           │          
                           └ <bound method UserServicer.GetUserList of <user_srv.handler.user.UserServicer object at 0x11048a100>>

  File "/Users/jianxiyan/home/练习/go_python/mxshop/mxshop_srvs/user_srv/handler/user.py", line 32, in GetUserList
    rsp = user_pb2.UserListResonse()
          └ <module 'user_srv.proto.user_pb2' from '/Users/jianxiyan/home/练习/go_python/mxshop/mxshop_srvs/user_srv/proto/user_pb2.py'>

AttributeError: module 'user_srv.proto.user_pb2' has no attribute 'UserListResonse'
