2021-07-17 19:51:20.584 | INFO     | __main__:serve:58 - 启动服务：127.0.0.1:8091
2021-07-17 19:53:46.077 | ERROR    | grpc._server:_call_behavior:444 - An error has been caught in function '_call_behavior', process 'MainProcess' (40656), thread 'ThreadPoolExecutor-0_0' (123145572270080):
Traceback (most recent call last):

  File "/Users/jianxiyan/anaconda3/envs/mxshop_srvs/lib/python3.8/threading.py", line 890, in _bootstrap
    self._bootstrap_inner()
    │    └ <function Thread._bootstrap_inner at 0x1008ee0d0>
    └ <Thread(ThreadPoolExecutor-0_0, started daemon 123145572270080)>
  File "/Users/jianxiyan/anaconda3/envs/mxshop_srvs/lib/python3.8/threading.py", line 932, in _bootstrap_inner
    self.run()
    │    └ <function Thread.run at 0x1008ebdc0>
    └ <Thread(ThreadPoolExecutor-0_0, started daemon 123145572270080)>
  File "/Users/jianxiyan/anaconda3/envs/mxshop_srvs/lib/python3.8/threading.py", line 870, in run
    self._target(*self._args, **self._kwargs)
    │    │        │    │        │    └ {}
    │    │        │    │        └ <Thread(ThreadPoolExecutor-0_0, started daemon 123145572270080)>
    │    │        │    └ (<weakref at 0x102667900; to 'ThreadPoolExecutor' at 0x10261e280>, <_queue.SimpleQueue object at 0x10261f400>, None, ())
    │    │        └ <Thread(ThreadPoolExecutor-0_0, started daemon 123145572270080)>
    │    └ <function _worker at 0x102632b80>
    └ <Thread(ThreadPoolExecutor-0_0, started daemon 123145572270080)>
  File "/Users/jianxiyan/anaconda3/envs/mxshop_srvs/lib/python3.8/concurrent/futures/thread.py", line 80, in _worker
    work_item.run()
    │         └ <function _WorkItem.run at 0x102632ca0>
    └ <concurrent.futures.thread._WorkItem object at 0x102630e20>
  File "/Users/jianxiyan/anaconda3/envs/mxshop_srvs/lib/python3.8/concurrent/futures/thread.py", line 57, in run
    result = self.fn(*self.args, **self.kwargs)
             │    │   │    │       │    └ {}
             │    │   │    │       └ <concurrent.futures.thread._WorkItem object at 0x102630e20>
             │    │   │    └ [<grpc._cython.cygrpc.RequestCallEvent object at 0x102667c70>, <grpc._server._RPCState object at 0x102630df0>, <bound method ...
             │    │   └ <concurrent.futures.thread._WorkItem object at 0x102630e20>
             │    └ <function _unary_response_in_pool at 0x10265d310>
             └ <concurrent.futures.thread._WorkItem object at 0x102630e20>
  File "/Users/jianxiyan/anaconda3/envs/mxshop_srvs/lib/python3.8/site-packages/grpc/_server.py", line 561, in _unary_response_in_pool
    response, proceed = _call_behavior(rpc_event, state, behavior,
                        │              │          │      └ <bound method UserServicer.GetUserByMobile of <user_srv.handler.user.UserServicer object at 0x10263a040>>
                        │              │          └ <grpc._server._RPCState object at 0x102630df0>
                        │              └ <grpc._cython.cygrpc.RequestCallEvent object at 0x102667c70>
                        └ <function _call_behavior at 0x102634ee0>
> File "/Users/jianxiyan/anaconda3/envs/mxshop_srvs/lib/python3.8/site-packages/grpc/_server.py", line 444, in _call_behavior
    response_or_iterator = behavior(argument, context)
                           │        │         └ <grpc._server._Context object at 0x10266f430>
                           │        └ 
                           └ <bound method UserServicer.GetUserByMobile of <user_srv.handler.user.UserServicer object at 0x10263a040>>

  File "/Users/jianxiyan/home/练习/go_python/mxshop/mxshop_srvs/user_srv/handler/user.py", line 70, in GetUserByMobile
    print(request.id)
          └

AttributeError: id
